
<mujoco model="dog">
  <compiler meshdir="dog_assets/" texturedir="dog_assets/"/>
  <include file="./common/skybox.xml"/>
  <include file="./common/visual.xml"/>
  <include file="./common/materials.xml"/>
  <option timestep="0.005" noslip_iterations="4"/>
  <size njmax="900" nconmax="300" nkey="1"/>
  <default>
    <joint limited="true" solreflimit="0.01 1" solimplimit="0.9 0.99 0.01" stiffness="0.1" armature="0.0001" damping="0.01"/>
    <geom friction="0.9" solref="0.01 1" solimp="0.95 0.99 0.001"/>
    <tendon rgba="0.5 0 0 1"/>
    <general ctrllimited="true" ctrlrange="-1 1" dyntype="filter" dynprm="0.05" gainprm="0.02"/>
    <default class="bone">
      <geom type="mesh" contype="0" conaffinity="0" group="5" rgba="0.5 0.5 0.5 1" density="1100.0"/>
      <default class="light_bone">
        <geom density="300.0"/>
      </default>
      <default class="visible_bone">
        <geom contype="0" conaffinity="0" group="1"/>
      </default>
    </default>
    <default class="collision_primitive">
      <geom type="capsule" contype="1" conaffinity="1" condim="1" group="3" rgba="0 0.5 0.5 1" density="300.0"/>
      <default class="foot_primitive">
        <geom rgba="0 0.6 0.4 1" solimp="0.9 0.95 0.001"/>
      </default>
      <default class="tooth_primitive">
        <geom condim="6" priority="2" friction="0.5 0.01 0.01"/>
      </default>
      <default class="nonself_collision_primitive">
        <geom conaffinity="0"/>
      </default>
    </default>
    <default class="connector">
      <site group="5" rgba="0 0.5 0 1" size="0.005"/>
    </default>
    <default class="muscle">
      <geom contype="0" conaffinity="0" group="4" rgba="0.5 0 0 1"/>
    </default>
    <default class="lumbar">
      <joint group="3" pos="0.012 0 0.01" armature="0.01" damping="3.0"/>
      <general gainprm="40"/>
      <default class="lumbar_extend">
        <joint stiffness="30.0" range="-24.5 24.5"/>
        <general gainprm="60"/>
      </default>
      <default class="lumbar_bend">
        <joint stiffness="45.0" range="-21 21"/>
      </default>
      <default class="lumbar_twist">
        <joint stiffness="45.0" range="-16.333 16.333"/>
      </default>
    </default>
    <default class="cervical">
      <joint group="3" pos="-0.7 0 0" stiffness="4.0" armature="0.01" damping="3.0"/>
      <default class="cervical_extend">
        <joint range="-17.5 61.25"/>
        <general gainprm="20"/>
      </default>
      <default class="cervical_bend">
        <joint range="-35 35"/>
        <general gainprm="20"/>
      </default>
      <default class="cervical_twist">
        <joint range="-23.333 23.333"/>
        <general gainprm="14"/>
      </default>
    </default>
    <default class="atlas">
      <joint axis="0 -1 0" stiffness="2.0" range="-15 30" damping="0.2"/>
      <general gainprm="10"/>
    </default>
    <default class="caudal">
      <joint group="3" springdamper="5e-05 15"/>
      <general gainprm="2"/>
      <default class="caudal_extend">
        <joint range="-15 15"/>
      </default>
      <default class="caudal_bend">
        <joint range="-15 15"/>
      </default>
    </default>
    <default class="mandible">
      <joint stiffness="2.0" range="-15 20" springref="-11.0" damping="0.2"/>
      <general gainprm="3"/>
    </default>
    <default class="hip">
      <joint stiffness="5.0" armature="0.01" damping="0.5"/>
      <general gainprm="10"/>
      <default class="hip_supinate">
        <joint range="-20 20"/>
      </default>
      <default class="hip_abduct">
        <joint range="-30 90"/>
      </default>
      <default class="hip_extend">
        <joint range="-130 60"/>
        <general gainprm="40"/>
      </default>
    </default>
    <default class="knee">
      <joint range="-120 10" damping="0.5"/>
      <general gainprm="30"/>
    </default>
    <default class="ankle">
      <joint range="-100 20" damping="0.3"/>
      <general gainprm="20"/>
    </default>
    <default class="toe">
      <joint stiffness="2.0" range="-15 70" damping="0.02"/>
      <general gainprm="2"/>
    </default>
    <default class="scapula">
      <joint stiffness="10.0" damping="1.5"/>
      <general gainprm="30"/>
      <default class="scapula_supinate">
        <joint pos="-0.03 0.02 0" range="-15 35"/>
      </default>
      <default class="scapula_abduct">
        <joint pos="0 0.05 -0.07" range="-15 20"/>
      </default>
      <default class="scapula_extend">
        <joint pos="0 0 0" range="-30 30"/>
        <general gainprm="30"/>
      </default>
    </default>
    <default class="shoulder">
      <joint stiffness="5.0" damping="1.0"/>
      <general gainprm="30"/>
      <default class="shoulder_extend">
        <joint range="-40 60"/>
      </default>
      <default class="shoulder_supinate">
        <joint range="-30 15"/>
      </default>
    </default>
    <default class="elbow">
      <joint range="-100 30" damping="0.3"/>
      <general gainprm="20"/>
    </default>
    <default class="wrist">
      <joint range="-110 10" damping="0.2"/>
      <general gainprm="10"/>
    </default>
    <default class="finger">
      <joint stiffness="1.0" range="-15 100" damping="0.02"/>
      <general gainprm="2"/>
    </default>
    <default class="sensor">
      <site group="4"/>
    </default>
    <default class="bouncy">
      <geom condim="6" priority="1" friction="0.5 0.001 0.001" solref="-5000 -5" solimp="0.5 0.9 0.01"/>
    </default>
    <default class="velcro">
      <geom condim="6" priority="2" friction="0.5 0.01 0.01"/>
    </default>
  </default>
  <visual>
    <global offwidth="1920" offheight="1080"/>
    <map znear="0.001"/>
    <scale jointlength="8.0" jointwidth="0.5" framelength="2.0" framewidth="0.3"/>
  </visual>
  <statistic meansize="0.01" extent="1.0"/>
  <asset>
    <mesh name="C_1" file="BONEC_1.stl"/>
    <mesh name="C_2" file="BONEC_2.stl"/>
    <mesh name="C_3" file="BONEC_3.stl"/>
    <mesh name="C_4" file="BONEC_4.stl"/>
    <mesh name="C_5" file="BONEC_5.stl"/>
    <mesh name="C_6" file="BONEC_6.stl"/>
    <mesh name="C_7" file="BONEC_7.stl"/>
    <mesh name="Ca_1" file="BONECa_1.stl"/>
    <mesh name="Ca_10" file="BONECa_10.stl"/>
    <mesh name="Ca_11" file="BONECa_11.stl"/>
    <mesh name="Ca_12" file="BONECa_12.stl"/>
    <mesh name="Ca_13" file="BONECa_13.stl"/>
    <mesh name="Ca_14" file="BONECa_14.stl"/>
    <mesh name="Ca_15" file="BONECa_15.stl"/>
    <mesh name="Ca_16" file="BONECa_16.stl"/>
    <mesh name="Ca_17" file="BONECa_17.stl"/>
    <mesh name="Ca_18" file="BONECa_18.stl"/>
    <mesh name="Ca_19" file="BONECa_19.stl"/>
    <mesh name="Ca_2" file="BONECa_2.stl"/>
    <mesh name="Ca_20" file="BONECa_20.stl"/>
    <mesh name="Ca_21" file="BONECa_21.stl"/>
    <mesh name="Ca_3" file="BONECa_3.stl"/>
    <mesh name="Ca_4" file="BONECa_4.stl"/>
    <mesh name="Ca_5" file="BONECa_5.stl"/>
    <mesh name="Ca_6" file="BONECa_6.stl"/>
    <mesh name="Ca_7" file="BONECa_7.stl"/>
    <mesh name="Ca_8" file="BONECa_8.stl"/>
    <mesh name="Ca_9" file="BONECa_9.stl"/>
    <mesh name="Calcaneal_tuber_L" file="BONECalcaneal_tuber_L.stl"/>
    <mesh name="Calcaneal_tuber_R" file="BONECalcaneal_tuber_R.stl"/>
    <mesh name="Carpal_III_L" file="BONECarpal_III_L.stl"/>
    <mesh name="Carpal_III_R" file="BONECarpal_III_R.stl"/>
    <mesh name="Carpal_II_L" file="BONECarpal_II_L.stl"/>
    <mesh name="Carpal_II_R" file="BONECarpal_II_R.stl"/>
    <mesh name="Carpal_IV_L" file="BONECarpal_IV_L.stl"/>
    <mesh name="Carpal_IV_R" file="BONECarpal_IV_R.stl"/>
    <mesh name="Carpal_I_L" file="BONECarpal_I_L.stl"/>
    <mesh name="Carpal_I_R" file="BONECarpal_I_R.stl"/>
    <mesh name="Carpal_L" file="BONECarpal_L.stl"/>
    <mesh name="Carpal_R" file="BONECarpal_R.stl"/>
    <mesh name="Carpal_Sesamoid_L" file="BONECarpal_Sesamoid_L.stl"/>
    <mesh name="Carpal_Sesamoid_R" file="BONECarpal_Sesamoid_R.stl"/>
    <mesh name="Carpal_accessory_L" file="BONECarpal_accessory_L.stl"/>
    <mesh name="Carpal_accessory_R" file="BONECarpal_accessory_R.stl"/>
    <mesh name="Carpal_ulnar_L" file="BONECarpal_ulnar_L.stl"/>
    <mesh name="Carpal_ulnar_R" file="BONECarpal_ulnar_R.stl"/>
    <mesh name="Femoris_L" file="BONEFemoris_L.stl"/>
    <mesh name="Femoris_R" file="BONEFemoris_R.stl"/>
    <mesh name="Femoris_fabellae_L_1" file="BONEFemoris_fabellae_L_1.stl"/>
    <mesh name="Femoris_fabellae_L_2" file="BONEFemoris_fabellae_L_2.stl"/>
    <mesh name="Femoris_fabellae_R_1" file="BONEFemoris_fabellae_R_1.stl"/>
    <mesh name="Femoris_fabellae_R_2" file="BONEFemoris_fabellae_R_2.stl"/>
    <mesh name="Fibula_L" file="BONEFibula_L.stl"/>
    <mesh name="Fibula_R" file="BONEFibula_R.stl"/>
    <mesh name="Jaw" file="BONEJaw.stl"/>
    <mesh name="L_1" file="BONEL_1.stl"/>
    <mesh name="L_2" file="BONEL_2.stl"/>
    <mesh name="L_3" file="BONEL_3.stl"/>
    <mesh name="L_4" file="BONEL_4.stl"/>
    <mesh name="L_5" file="BONEL_5.stl"/>
    <mesh name="L_6" file="BONEL_6.stl"/>
    <mesh name="L_7" file="BONEL_7.stl"/>
    <mesh name="MergedSkull" file="BONEMergedSkull.stl"/>
    <mesh name="Metatarsi_L_1" file="BONEMetatarsi_L_1.stl"/>
    <mesh name="Metatarsi_L_2" file="BONEMetatarsi_L_2.stl"/>
    <mesh name="Metatarsi_L_3" file="BONEMetatarsi_L_3.stl"/>
    <mesh name="Metatarsi_L_4" file="BONEMetatarsi_L_4.stl"/>
    <mesh name="Metatarsi_R_1" file="BONEMetatarsi_R_1.stl"/>
    <mesh name="Metatarsi_R_2" file="BONEMetatarsi_R_2.stl"/>
    <mesh name="Metatarsi_R_3" file="BONEMetatarsi_R_3.stl"/>
    <mesh name="Metatarsi_R_4" file="BONEMetatarsi_R_4.stl"/>
    <mesh name="Os_metacarpale_III_L" file="BONEOs_metacarpale_III_L.stl"/>
    <mesh name="Os_metacarpale_III_R" file="BONEOs_metacarpale_III_R.stl"/>
    <mesh name="Os_metacarpale_II_L" file="BONEOs_metacarpale_II_L.stl"/>
    <mesh name="Os_metacarpale_II_R" file="BONEOs_metacarpale_II_R.stl"/>
    <mesh name="Os_metacarpale_IV_L" file="BONEOs_metacarpale_IV_L.stl"/>
    <mesh name="Os_metacarpale_IV_R" file="BONEOs_metacarpale_IV_R.stl"/>
    <mesh name="Os_metacarpale_I_L" file="BONEOs_metacarpale_I_L.stl"/>
    <mesh name="Os_metacarpale_I_R" file="BONEOs_metacarpale_I_R.stl"/>
    <mesh name="Os_metacarpale_V_L.001" file="BONEOs_metacarpale_V_L.001.stl"/>
    <mesh name="Os_metacarpale_V_L" file="BONEOs_metacarpale_V_L.stl"/>
    <mesh name="Os_metacarpale_V_R.001" file="BONEOs_metacarpale_V_R.001.stl"/>
    <mesh name="Os_metacarpale_V_R" file="BONEOs_metacarpale_V_R.stl"/>
    <mesh name="Patella_L" file="BONEPatella_L.stl"/>
    <mesh name="Patella_R" file="BONEPatella_R.stl"/>
    <mesh name="Pelvis" file="BONEPelvis.stl"/>
    <mesh name="Phalanges_B_2_L_1" file="BONEPhalanges_B_2_L_1.stl"/>
    <mesh name="Phalanges_B_2_L_2" file="BONEPhalanges_B_2_L_2.stl"/>
    <mesh name="Phalanges_B_2_L_3" file="BONEPhalanges_B_2_L_3.stl"/>
    <mesh name="Phalanges_B_2_L_4" file="BONEPhalanges_B_2_L_4.stl"/>
    <mesh name="Phalanges_B_2_R_1" file="BONEPhalanges_B_2_R_1.stl"/>
    <mesh name="Phalanges_B_2_R_2" file="BONEPhalanges_B_2_R_2.stl"/>
    <mesh name="Phalanges_B_2_R_3" file="BONEPhalanges_B_2_R_3.stl"/>
    <mesh name="Phalanges_B_2_R_4" file="BONEPhalanges_B_2_R_4.stl"/>
    <mesh name="Phalanges_B_3_L_1" file="BONEPhalanges_B_3_L_1.stl"/>
    <mesh name="Phalanges_B_3_L_2" file="BONEPhalanges_B_3_L_2.stl"/>
    <mesh name="Phalanges_B_3_L_3" file="BONEPhalanges_B_3_L_3.stl"/>
    <mesh name="Phalanges_B_3_L_4" file="BONEPhalanges_B_3_L_4.stl"/>
    <mesh name="Phalanges_B_3_R_1" file="BONEPhalanges_B_3_R_1.stl"/>
    <mesh name="Phalanges_B_3_R_2" file="BONEPhalanges_B_3_R_2.stl"/>
    <mesh name="Phalanges_B_3_R_3" file="BONEPhalanges_B_3_R_3.stl"/>
    <mesh name="Phalanges_B_3_R_4" file="BONEPhalanges_B_3_R_4.stl"/>
    <mesh name="Phalanges_B_L_1" file="BONEPhalanges_B_L_1.stl"/>
    <mesh name="Phalanges_B_L_2" file="BONEPhalanges_B_L_2.stl"/>
    <mesh name="Phalanges_B_L_3" file="BONEPhalanges_B_L_3.stl"/>
    <mesh name="Phalanges_B_L_4" file="BONEPhalanges_B_L_4.stl"/>
    <mesh name="Phalanges_B_R_1" file="BONEPhalanges_B_R_1.stl"/>
    <mesh name="Phalanges_B_R_2" file="BONEPhalanges_B_R_2.stl"/>
    <mesh name="Phalanges_B_R_3" file="BONEPhalanges_B_R_3.stl"/>
    <mesh name="Phalanges_B_R_4" file="BONEPhalanges_B_R_4.stl"/>
    <mesh name="Phalanx_distalis_digiti_III_L" file="BONEPhalanx_distalis_digiti_III_L.stl"/>
    <mesh name="Phalanx_distalis_digiti_III_R" file="BONEPhalanx_distalis_digiti_III_R.stl"/>
    <mesh name="Phalanx_distalis_digiti_II_L" file="BONEPhalanx_distalis_digiti_II_L.stl"/>
    <mesh name="Phalanx_distalis_digiti_II_R" file="BONEPhalanx_distalis_digiti_II_R.stl"/>
    <mesh name="Phalanx_distalis_digiti_IV_L" file="BONEPhalanx_distalis_digiti_IV_L.stl"/>
    <mesh name="Phalanx_distalis_digiti_IV_R" file="BONEPhalanx_distalis_digiti_IV_R.stl"/>
    <mesh name="Phalanx_distalis_digiti_I_L" file="BONEPhalanx_distalis_digiti_I_L.stl"/>
    <mesh name="Phalanx_distalis_digiti_I_R" file="BONEPhalanx_distalis_digiti_I_R.stl"/>
    <mesh name="Phalanx_distalis_digiti_V_L" file="BONEPhalanx_distalis_digiti_V_L.stl"/>
    <mesh name="Phalanx_distalis_digiti_V_R" file="BONEPhalanx_distalis_digiti_V_R.stl"/>
    <mesh name="Phalanx_media_digiti_III_L" file="BONEPhalanx_media_digiti_III_L.stl"/>
    <mesh name="Phalanx_media_digiti_III_R" file="BONEPhalanx_media_digiti_III_R.stl"/>
    <mesh name="Phalanx_media_digiti_II_L" file="BONEPhalanx_media_digiti_II_L.stl"/>
    <mesh name="Phalanx_media_digiti_II_R" file="BONEPhalanx_media_digiti_II_R.stl"/>
    <mesh name="Phalanx_media_digiti_IV_L" file="BONEPhalanx_media_digiti_IV_L.stl"/>
    <mesh name="Phalanx_media_digiti_IV_R" file="BONEPhalanx_media_digiti_IV_R.stl"/>
    <mesh name="Phalanx_media_digiti_V_L" file="BONEPhalanx_media_digiti_V_L.stl"/>
    <mesh name="Phalanx_media_digiti_V_R" file="BONEPhalanx_media_digiti_V_R.stl"/>
    <mesh name="Phalanxpmxinutlis_digiti_III_L_" file="BONEPhalanxpmxinutlis_digiti_III_L_.stl"/>
    <mesh name="Phalanxpmxinutlis_digiti_III_R" file="BONEPhalanxpmxinutlis_digiti_III_R.stl"/>
    <mesh name="Phalanxpmxinutlis_digiti_II_L" file="BONEPhalanxpmxinutlis_digiti_II_L.stl"/>
    <mesh name="Phalanxpmxinutlis_digiti_II_R" file="BONEPhalanxpmxinutlis_digiti_II_R.stl"/>
    <mesh name="Phalanxpmxinutlis_digiti_IV_L_" file="BONEPhalanxpmxinutlis_digiti_IV_L_.stl"/>
    <mesh name="Phalanxpmxinutlis_digiti_IV_R" file="BONEPhalanxpmxinutlis_digiti_IV_R.stl"/>
    <mesh name="Phalanxpmxinutlis_digiti_V_L" file="BONEPhalanxpmxinutlis_digiti_V_L.stl"/>
    <mesh name="Phalanxpmxinutlis_digiti_V_R" file="BONEPhalanxpmxinutlis_digiti_V_R.stl"/>
    <mesh name="Radius_L" file="BONERadius_L.stl"/>
    <mesh name="Radius_R" file="BONERadius_R.stl"/>
    <mesh name="Ribcage" file="BONERibcage.stl"/>
    <mesh name="Sacrum" file="BONESacrum.stl"/>
    <mesh name="Scapula_L" file="BONEScapula_L.stl"/>
    <mesh name="Scapula_R" file="BONEScapula_R.stl"/>
    <mesh name="Tarsus_L_I" file="BONETarsus_L_I.stl"/>
    <mesh name="Tarsus_L_II" file="BONETarsus_L_II.stl"/>
    <mesh name="Tarsus_L_III" file="BONETarsus_L_III.stl"/>
    <mesh name="Tarsus_L_IV" file="BONETarsus_L_IV.stl"/>
    <mesh name="Tarsus_R_I" file="BONETarsus_R_I.stl"/>
    <mesh name="Tarsus_R_II" file="BONETarsus_R_II.stl"/>
    <mesh name="Tarsus_R_III" file="BONETarsus_R_III.stl"/>
    <mesh name="Tarsus_R_IV" file="BONETarsus_R_IV.stl"/>
    <mesh name="Tarsus_central_L" file="BONETarsus_central_L.stl"/>
    <mesh name="Tarsus_central_R" file="BONETarsus_central_R.stl"/>
    <mesh name="Tibia_L" file="BONETibia_L.stl"/>
    <mesh name="Tibia_R" file="BONETibia_R.stl"/>
    <mesh name="Tibial_tarsal_L" file="BONETibial_tarsal_L.stl"/>
    <mesh name="Tibial_tarsal_R" file="BONETibial_tarsal_R.stl"/>
    <mesh name="Ulna_L" file="BONEUlna_L.stl"/>
    <mesh name="Ulna_R" file="BONEUlna_R.stl"/>
    <mesh name="eye_L" file="BONEeye_L.stl"/>
    <mesh name="eye_R" file="BONEeye_R.stl"/>
    <mesh name="humerus_L" file="BONEhumerus_L.stl"/>
    <mesh name="humerus_R" file="BONEhumerus_R.stl"/>
    <texture name="skin" type="2d" file="skin_texture.png"/>
    <material name="skin" texture="skin"/>
    <skin name="skin" file="dog_skin.skn" material="skin"/>
    <texture name="tennis_ball" file="tennis_ball.png" gridsize="3 4" gridlayout=".U..LFRB.D.."/>
    <material name="tennis_ball" texture="tennis_ball"/>
  </asset>
  <worldbody>
    <geom name="floor" type="plane" size="10 10 0.1" material="grid"/>
    <body name="torso" pos="0.040403 0 0.41522">
      <freejoint name="root"/>
      <light name="light" mode="trackcom" pos="0 0 3"/>
      <camera name="y-axis" mode="trackcom" pos="0 -1.5 0.8" xyaxes="1 0 0 0 0.6 1"/>
      <camera name="x-axis" mode="trackcom" pos="2 0 0.5" xyaxes="0 1 0 -0.3 0 1"/>
      <geom name="collision_torso" class="nonself_collision_primitive" type="ellipsoid" size="0.2 0.09 0.11" density="200.0" pos="0 0 0" euler="0 10 0"/>
      <body name="L_1" pos="-0.1235 0 0.09287">
        <geom name="L_1" class="bone" pos="0.083094 0 -0.50809" mesh="L_1"/>
        <geom name="L_1_collision" class="nonself_collision_primitive" type="sphere" size="0.05" pos="0 0 -0.02"/>
        <body name="L_2" pos="-0.023024 0 0.00096026">
          <geom name="L_2" class="bone" pos="0.10612 0 -0.50905" mesh="L_2"/>
          <geom name="L_2_collision" class="nonself_collision_primitive" type="sphere" size="0.05" pos="0 0 -0.02"/>
          <body name="L_3" pos="-0.0233 0 0.00039242">
            <geom name="L_3" class="bone" pos="0.12942 0 -0.50944" mesh="L_3"/>
            <geom name="L_3_collision" class="nonself_collision_primitive" type="sphere" size="0.05" pos="0 0 -0.02"/>
            <body name="L_4" pos="-0.024246 0 -0.00041778">
              <geom name="L_4" class="bone" pos="0.15366 0 -0.50903" mesh="L_4"/>
              <geom name="L_4_collision" class="nonself_collision_primitive" type="sphere" size="0.05" pos="0 0 -0.02"/>
              <body name="L_5" pos="-0.024458 0 -0.00014988">
                <geom name="L_5" class="bone" pos="0.17812 0 -0.50888" mesh="L_5"/>
                <geom name="L_5_collision" class="nonself_collision_primitive" type="sphere" size="0.05" pos="0 0 -0.02"/>
                <body name="L_6" pos="-0.023445 0 0.00066898">
                  <geom name="L_6" class="bone" pos="0.20157 0 -0.50954" mesh="L_6"/>
                  <geom name="L_6_collision" class="nonself_collision_primitive" type="sphere" size="0.05" pos="0 0 -0.02"/>
                  <body name="L_7" pos="-0.026399 0 0.0014219">
                    <geom name="L_7" class="bone" pos="0.22797 0 -0.51097" mesh="L_7"/>
                    <geom name="L_7_collision" class="nonself_collision_primitive" type="sphere" size="0.05" pos="0 0 -0.02"/>
                    <joint name="L_7_extend" class="lumbar_extend" axis="0 1 0"/>
                    <joint name="L_7_bend" class="lumbar_bend" axis="0 0 1"/>
                    <body name="pelvis" pos="-0.080217 0 -0.034801">
                      <geom name="Sacrum" class="bone" pos="0.30818 0 -0.47617" mesh="Sacrum"/>
                      <geom name="Pelvis" class="bone" pos="0.30818 0 -0.47617" mesh="Pelvis"/>
                      <geom name="collision_pelvis_L" class="nonself_collision_primitive" size="0.05 0.05 0" pos="0.01 0.02 -0.01" euler="0 70 0"/>
                      <geom name="collision_pelvis_R" class="nonself_collision_primitive" size="0.05 0.05 0" pos="0.01 -0.02 -0.01" euler="0 70 0"/>
                      <body name="upper_leg_L" pos="-0.018108 0.047237 -0.012597">
                        <geom name="Femoris_L" class="bone" pos="0.32629 -0.047237 -0.46357" mesh="Femoris_L"/>
                        <geom name="Femoris_fabellae_L_1" class="bone" pos="0.32629 -0.047237 -0.46357" mesh="Femoris_fabellae_L_1"/>
                        <geom name="Femoris_fabellae_L_2" class="bone" pos="0.32629 -0.047237 -0.46357" mesh="Femoris_fabellae_L_2"/>
                        <geom name="Patella_L" class="bone" pos="0.32629 -0.047237 -0.46357" mesh="Patella_L"/>
                        <joint name="hip_L_supinate" class="hip_supinate" axis="0 0 1"/>
                        <joint name="hip_L_abduct" class="hip_abduct" axis="1 0 0"/>
                        <joint name="hip_L_extend" class="hip_extend" axis="0 1 0"/>
                        <geom name="upper_leg_L0_collision" class="collision_primitive" size="0.04 0.08" pos="-0.01 0.02 -0.08" euler="10 20 0"/>
                        <geom name="upper_leg_L1_collision" class="collision_primitive" size="0.04 0.04" pos="-0.03 0 -0.05" euler="10 5 0"/>
                        <body name="lower_leg_L" pos="-0.023037 0.0311 -0.16702">
                          <geom name="Fibula_L" class="bone" pos="0.34933 -0.078337 -0.29655" mesh="Fibula_L"/>
                          <geom name="Tibia_L" class="bone" pos="0.34933 -0.078337 -0.29655" mesh="Tibia_L"/>
                          <joint name="knee_L" class="knee" axis="0 -1 0"/>
                          <body name="foot_L" pos="-0.17914 -0.0056423 -0.13824">
                            <geom name="Calcaneal_tuber_L" class="bone" pos="0.52847 -0.072695 -0.15831" mesh="Calcaneal_tuber_L"/>
                            <geom name="Metatarsi_L_1" class="bone" pos="0.52847 -0.072695 -0.15831" mesh="Metatarsi_L_1"/>
                            <geom name="Metatarsi_L_2" class="bone" pos="0.52847 -0.072695 -0.15831" mesh="Metatarsi_L_2"/>
                            <geom name="Metatarsi_L_3" class="bone" pos="0.52847 -0.072695 -0.15831" mesh="Metatarsi_L_3"/>
                            <geom name="Metatarsi_L_4" class="bone" pos="0.52847 -0.072695 -0.15831" mesh="Metatarsi_L_4"/>
                            <geom name="Tarsus_L_I" class="bone" pos="0.52847 -0.072695 -0.15831" mesh="Tarsus_L_I"/>
                            <geom name="Tarsus_L_II" class="bone" pos="0.52847 -0.072695 -0.15831" mesh="Tarsus_L_II"/>
                            <geom name="Tarsus_L_III" class="bone" pos="0.52847 -0.072695 -0.15831" mesh="Tarsus_L_III"/>
                            <geom name="Tarsus_L_IV" class="bone" pos="0.52847 -0.072695 -0.15831" mesh="Tarsus_L_IV"/>
                            <geom name="Tarsus_central_L" class="bone" pos="0.52847 -0.072695 -0.15831" mesh="Tarsus_central_L"/>
                            <geom name="Tibial_tarsal_L" class="bone" pos="0.52847 -0.072695 -0.15831" mesh="Tibial_tarsal_L"/>
                            <joint name="ankle_L" class="ankle" axis="0 1 0"/>
                            <geom name="foot_L_collision" class="collision_primitive" size="0.015 0.07" pos="-0.01 0.005 -0.05"/>
                            <body name="foot_anchor_L" pos="-0.015043 0.0081311 -0.11993">
                              <geom name="foot_anchor_L" class="foot_primitive" type="box" contype="0" conaffinity="0" size="0.005 0.005 0.005"/>
                              <site name="foot_anchor_L" class="sensor"/>
                              <body name="toe_L">
                                <geom name="Phalanges_B_2_L_1" class="bone" pos="0.54351 -0.080826 -0.03838" mesh="Phalanges_B_2_L_1"/>
                                <geom name="Phalanges_B_2_L_2" class="bone" pos="0.54351 -0.080826 -0.03838" mesh="Phalanges_B_2_L_2"/>
                                <geom name="Phalanges_B_2_L_3" class="bone" pos="0.54351 -0.080826 -0.03838" mesh="Phalanges_B_2_L_3"/>
                                <geom name="Phalanges_B_2_L_4" class="bone" pos="0.54351 -0.080826 -0.03838" mesh="Phalanges_B_2_L_4"/>
                                <geom name="Phalanges_B_3_L_1" class="visible_bone" pos="0.54351 -0.080826 -0.03838" mesh="Phalanges_B_3_L_1"/>
                                <geom name="Phalanges_B_3_L_2" class="visible_bone" pos="0.54351 -0.080826 -0.03838" mesh="Phalanges_B_3_L_2"/>
                                <geom name="Phalanges_B_3_L_3" class="visible_bone" pos="0.54351 -0.080826 -0.03838" mesh="Phalanges_B_3_L_3"/>
                                <geom name="Phalanges_B_3_L_4" class="visible_bone" pos="0.54351 -0.080826 -0.03838" mesh="Phalanges_B_3_L_4"/>
                                <geom name="Phalanges_B_L_1" class="bone" pos="0.54351 -0.080826 -0.03838" mesh="Phalanges_B_L_1"/>
                                <geom name="Phalanges_B_L_2" class="bone" pos="0.54351 -0.080826 -0.03838" mesh="Phalanges_B_L_2"/>
                                <geom name="Phalanges_B_L_3" class="bone" pos="0.54351 -0.080826 -0.03838" mesh="Phalanges_B_L_3"/>
                                <geom name="Phalanges_B_L_4" class="bone" pos="0.54351 -0.080826 -0.03838" mesh="Phalanges_B_L_4"/>
                                <joint name="toe_L" class="toe" axis="0 1 0"/>
                                <geom name="toe_L0_collision" class="foot_primitive" size="0.018 0.012" pos="0.015 0 -0.02" euler="90 0 0"/>
                                <geom name="toe_L1_collision" class="foot_primitive" size="0.01 0.015" pos="0.035 0 -0.028" euler="90 0 0"/>
                                <geom name="toe_L2_collision" class="foot_primitive" size="0.008 0.01" pos="0.045 0 -0.03" euler="90 0 0"/>
                                <site name="sole_L" class="sensor" type="box" size="0.025 0.03 0.008" pos="0.026 0 -0.033"/>
                              </body>
                            </body>
                          </body>
                          <geom name="lower_leg_L_collision" class="collision_primitive" size="0.02 0.1" pos="-0.09513 -1.1454e-05 -0.068643" quat="0.80051 0.18703 0.42091 0.38345"/>
                        </body>
                      </body>
                      <body name="upper_leg_R" pos="-0.018108 -0.047237 -0.012597">
                        <geom name="Femoris_R" class="bone" pos="0.32629 0.047237 -0.46357" mesh="Femoris_R"/>
                        <geom name="Femoris_fabellae_R_1" class="bone" pos="0.32629 0.047237 -0.46357" mesh="Femoris_fabellae_R_1"/>
                        <geom name="Femoris_fabellae_R_2" class="bone" pos="0.32629 0.047237 -0.46357" mesh="Femoris_fabellae_R_2"/>
                        <geom name="Patella_R" class="bone" pos="0.32629 0.047237 -0.46357" mesh="Patella_R"/>
                        <joint name="hip_R_supinate" class="hip_supinate" axis="0 0 -1"/>
                        <joint name="hip_R_abduct" class="hip_abduct" axis="-1 0 0"/>
                        <joint name="hip_R_extend" class="hip_extend" axis="0 1 0"/>
                        <geom name="upper_leg_R0_collision" class="collision_primitive" size="0.04 0.08" pos="-0.01 -0.02 -0.08" euler="-10 20 0"/>
                        <geom name="upper_leg_R1_collision" class="collision_primitive" size="0.04 0.04" pos="-0.03 0 -0.05" euler="-10 5 0"/>
                        <body name="lower_leg_R" pos="-0.023037 -0.0311 -0.16702">
                          <geom name="Fibula_R" class="bone" pos="0.34933 0.078337 -0.29655" mesh="Fibula_R"/>
                          <geom name="Tibia_R" class="bone" pos="0.34933 0.078337 -0.29655" mesh="Tibia_R"/>
                          <joint name="knee_R" class="knee" axis="0 -1 0"/>
                          <body name="foot_R" pos="-0.17914 0.0056423 -0.13824">
                            <geom name="Calcaneal_tuber_R" class="bone" pos="0.52847 0.072695 -0.15831" mesh="Calcaneal_tuber_R"/>
                            <geom name="Metatarsi_R_1" class="bone" pos="0.52847 0.072695 -0.15831" mesh="Metatarsi_R_1"/>
                            <geom name="Metatarsi_R_2" class="bone" pos="0.52847 0.072695 -0.15831" mesh="Metatarsi_R_2"/>
                            <geom name="Metatarsi_R_3" class="bone" pos="0.52847 0.072695 -0.15831" mesh="Metatarsi_R_3"/>
                            <geom name="Metatarsi_R_4" class="bone" pos="0.52847 0.072695 -0.15831" mesh="Metatarsi_R_4"/>
                            <geom name="Tarsus_R_I" class="bone" pos="0.52847 0.072695 -0.15831" mesh="Tarsus_R_I"/>
                            <geom name="Tarsus_R_II" class="bone" pos="0.52847 0.072695 -0.15831" mesh="Tarsus_R_II"/>
                            <geom name="Tarsus_R_III" class="bone" pos="0.52847 0.072695 -0.15831" mesh="Tarsus_R_III"/>
                            <geom name="Tarsus_R_IV" class="bone" pos="0.52847 0.072695 -0.15831" mesh="Tarsus_R_IV"/>
                            <geom name="Tarsus_central_R" class="bone" pos="0.52847 0.072695 -0.15831" mesh="Tarsus_central_R"/>
                            <geom name="Tibial_tarsal_R" class="bone" pos="0.52847 0.072695 -0.15831" mesh="Tibial_tarsal_R"/>
                            <joint name="ankle_R" class="ankle" axis="0 1 0"/>
                            <geom name="foot_R_collision" class="collision_primitive" size="0.015 0.07" pos="-0.01 -0.005 -0.05"/>
                            <body name="foot_anchor_R" pos="-0.015043 -0.0081311 -0.11993">
                              <geom name="foot_anchor_R" class="foot_primitive" type="box" contype="0" conaffinity="0" size="0.005 0.005 0.005"/>
                              <site name="foot_anchor_R" class="sensor"/>
                              <body name="toe_R">
                                <geom name="Phalanges_B_2_R_1" class="bone" pos="0.54351 0.080826 -0.03838" mesh="Phalanges_B_2_R_1"/>
                                <geom name="Phalanges_B_2_R_2" class="bone" pos="0.54351 0.080826 -0.03838" mesh="Phalanges_B_2_R_2"/>
                                <geom name="Phalanges_B_2_R_3" class="bone" pos="0.54351 0.080826 -0.03838" mesh="Phalanges_B_2_R_3"/>
                                <geom name="Phalanges_B_2_R_4" class="bone" pos="0.54351 0.080826 -0.03838" mesh="Phalanges_B_2_R_4"/>
                                <geom name="Phalanges_B_3_R_1" class="visible_bone" pos="0.54351 0.080826 -0.03838" mesh="Phalanges_B_3_R_1"/>
                                <geom name="Phalanges_B_3_R_2" class="visible_bone" pos="0.54351 0.080826 -0.03838" mesh="Phalanges_B_3_R_2"/>
                                <geom name="Phalanges_B_3_R_3" class="visible_bone" pos="0.54351 0.080826 -0.03838" mesh="Phalanges_B_3_R_3"/>
                                <geom name="Phalanges_B_3_R_4" class="visible_bone" pos="0.54351 0.080826 -0.03838" mesh="Phalanges_B_3_R_4"/>
                                <geom name="Phalanges_B_R_1" class="bone" pos="0.54351 0.080826 -0.03838" mesh="Phalanges_B_R_1"/>
                                <geom name="Phalanges_B_R_2" class="bone" pos="0.54351 0.080826 -0.03838" mesh="Phalanges_B_R_2"/>
                                <geom name="Phalanges_B_R_3" class="bone" pos="0.54351 0.080826 -0.03838" mesh="Phalanges_B_R_3"/>
                                <geom name="Phalanges_B_R_4" class="bone" pos="0.54351 0.080826 -0.03838" mesh="Phalanges_B_R_4"/>
                                <joint name="toe_R" class="toe" axis="0 1 0"/>
                                <geom name="toe_R0_collision" class="foot_primitive" size="0.018 0.012" pos="0.015 0 -0.02" euler="90 0 0"/>
                                <geom name="toe_R1_collision" class="foot_primitive" size="0.01 0.015" pos="0.035 0 -0.028" euler="90 0 0"/>
                                <geom name="toe_R2_collision" class="foot_primitive" size="0.008 0.01" pos="0.045 0 -0.03" euler="90 0 0"/>
                                <site name="sole_R" class="sensor" type="box" size="0.025 0.03 0.008" pos="0.026 0 -0.033"/>
                              </body>
                            </body>
                          </body>
                          <geom name="lower_leg_R_collision" class="collision_primitive" size="0.02 0.1" pos="-0.09513 1.136e-05 -0.068643" quat="0.38345 0.42091 0.18703 0.80051"/>
                        </body>
                      </body>
                      <body name="Ca_1" pos="0.0082462 0 0.04354">
                        <geom name="Ca_1" class="bone" pos="0.29994 0 -0.51971" mesh="Ca_1"/>
                        <body name="Ca_2" pos="-0.01491 0 4.6796e-05">
                          <geom name="Ca_2" class="bone" pos="0.31485 0 -0.51975" mesh="Ca_2"/>
                          <body name="Ca_3" pos="-0.01408 0 -0.0010873">
                            <geom name="Ca_3" class="bone" pos="0.32893 0 -0.51867" mesh="Ca_3"/>
                            <body name="Ca_4" pos="-0.012508 0 -0.002837">
                              <geom name="Ca_4" class="bone" pos="0.34144 0 -0.51583" mesh="Ca_4"/>
                              <body name="Ca_5" pos="-0.013783 -1.652e-06 -0.0065348">
                                <geom name="Ca_5" class="bone" pos="0.35522 1.687e-06 -0.50929" mesh="Ca_5"/>
                                <body name="Ca_6" pos="-0.016384 -1.0009e-05 -0.0098338">
                                  <geom name="Ca_6" class="bone" pos="0.3716 1.1696e-05 -0.49946" mesh="Ca_6"/>
                                  <body name="Ca_7" pos="-0.016206 1.4193e-05 -0.011471">
                                    <geom name="Ca_7" class="bone" pos="0.38781 -2.4968e-06 -0.48799" mesh="Ca_7"/>
                                    <body name="Ca_8" pos="-0.018452 0.00021258 -0.013121">
                                      <geom name="Ca_8" class="bone" pos="0.40626 -0.00021508 -0.47487" mesh="Ca_8"/>
                                      <body name="Ca_9" pos="-0.019834 -1.086e-05 -0.017678">
                                        <geom name="Ca_9" class="bone" pos="0.42609 -0.00020422 -0.45719" mesh="Ca_9"/>
                                        <body name="Ca_10" pos="-0.023389 1.1411e-05 -0.022029">
                                          <geom name="Ca_10" class="bone" pos="0.44948 -0.00021563 -0.43516" mesh="Ca_10"/>
                                          <body name="Ca_11" pos="-0.024196 -5.3444e-06 -0.022377">
                                            <geom name="Ca_11" class="bone" pos="0.47368 -0.00021028 -0.41278" mesh="Ca_11"/>
                                            <body name="Ca_12" pos="-0.024081 -5.5423e-05 -0.019678">
                                              <geom name="Ca_12" class="bone" pos="0.49776 -0.00015486 -0.39311" mesh="Ca_12"/>
                                              <body name="Ca_13" pos="-0.02323 -1.2027e-05 -0.017776">
                                                <geom name="Ca_13" class="bone" pos="0.52099 -0.00014283 -0.37533" mesh="Ca_13"/>
                                                <body name="Ca_14" pos="-0.023245 -9.0352e-05 -0.018326">
                                                  <geom name="Ca_14" class="bone" pos="0.54424 -5.2481e-05 -0.357" mesh="Ca_14"/>
                                                  <body name="Ca_15" pos="-0.024641 5.041e-05 -0.014254">
                                                    <geom name="Ca_15" class="bone" pos="0.56888 -0.00010289 -0.34275" mesh="Ca_15"/>
                                                    <body name="Ca_16" pos="-0.023338 -3.1369e-05 -0.0085014">
                                                      <geom name="Ca_16" class="bone" pos="0.59221 -7.1522e-05 -0.33425" mesh="Ca_16"/>
                                                      <body name="Ca_17" pos="-0.024444 -1.4083e-05 -0.0053673">
                                                        <geom name="Ca_17" class="bone" pos="0.61666 -5.7439e-05 -0.32888" mesh="Ca_17"/>
                                                        <body name="Ca_18" pos="-0.02601 1.3546e-05 -0.0022059">
                                                          <geom name="Ca_18" class="bone" pos="0.64267 -7.0985e-05 -0.32667" mesh="Ca_18"/>
                                                          <body name="Ca_19" pos="-0.026655 3.2028e-05 0.00068575">
                                                            <geom name="Ca_19" class="bone" pos="0.66932 -0.00010301 -0.32736" mesh="Ca_19"/>
                                                            <body name="Ca_20" pos="-0.026838 -6.5667e-05 0.0040269">
                                                            <geom name="Ca_20" class="bone" pos="0.69616 -3.7346e-05 -0.33139" mesh="Ca_20"/>
                                                            <body name="Ca_21" pos="-0.020294 4.4629e-05 0.0048627">
                                                            <geom name="Ca_21" class="bone" pos="0.71646 -8.1976e-05 -0.33625" mesh="Ca_21"/>